2022-11-02 11:14:16,615 ERROR    C:\Users\1\PROJECTS\pythonProject\News_PortalD10\venv\lib\site-packages\django\utils\log.py (<class 'django.contrib.auth.models.Group.DoesNotExist'>, DoesNotExist('Group matching query does not exist.'), <traceback object at 0x0000018C09FAEA40>) Internal Server Error: /sign/upgrade_me/
Traceback (most recent call last):
  File "C:\Users\1\PROJECTS\pythonProject\News_PortalD10\venv\lib\site-packages\django\core\handlers\exception.py", line 55, in inner
    response = get_response(request)
  File "C:\Users\1\PROJECTS\pythonProject\News_PortalD10\venv\lib\site-packages\django\core\handlers\base.py", line 197, in _get_response
    response = wrapped_callback(request, *callback_args, **callback_kwargs)
  File "C:\Users\1\PROJECTS\pythonProject\News_PortalD10\venv\lib\site-packages\django\contrib\auth\decorators.py", line 23, in _wrapped_view
    return view_func(request, *args, **kwargs)
  File "C:\Users\1\PROJECTS\pythonProject\News_PortalD10\News_Portal\sign\views.py", line 29, in upgrade_me
    author_group = Group.objects.get(name='authors')
  File "C:\Users\1\PROJECTS\pythonProject\News_PortalD10\venv\lib\site-packages\django\db\models\manager.py", line 85, in manager_method
    return getattr(self.get_queryset(), name)(*args, **kwargs)
  File "C:\Users\1\PROJECTS\pythonProject\News_PortalD10\venv\lib\site-packages\django\db\models\query.py", line 650, in get
    raise self.model.DoesNotExist(
django.contrib.auth.models.Group.DoesNotExist: Group matching query does not exist.
2022-11-02 11:14:16,624 ERROR    C:\Users\1\PROJECTS\pythonProject\News_PortalD10\venv\lib\site-packages\django\core\servers\basehttp.py None     "GET /sign/upgrade_me/ HTTP/1.1" 500 88927
2022-11-02 14:23:01,558 ERROR    C:\Users\1\PROJECTS\pythonProject\News_PortalD10\venv\lib\site-packages\django\core\servers\basehttp.py None     "GET /posts/15/ HTTP/1.1" 500 89514
